----------------------------------------------------
--      ___     _                   _   _         --
--     / __| __| |_  ___ _ __  __ _| |_(_)__      --
--     \__ \/ _| ' \/ -_) '  \/ _` |  _| / _|     --
--     |___/\__|_||_\___|_|_|_\__,_|\__|_\__|     --
--   ___                      _   _               --
--  |   \ ___ __ ___ _ _ __ _| |_(_)___ _ _  ___  --
--  | |) / -_) _/ _ \ '_/ _` |  _| / _ \ ' \(_-<  --
--  |___/\___\__\___/_| \__,_|\__|_\___/_||_/__/  --
----------------------------------------------------
--           MTG Decorations Schematic            --
----------------------------------------------------
--        Jungle Tree Emergent Schematic          --
----------------------------------------------------

--Shortened path to schematic table
local path = mtg_decor_schema.schematic

-- Check for Aliases 
-- helps future proof name changes so long as alias tables are kept upto date
-- See - https://rubenwardy.com/minetest_modding_book/en/items/nodes_items_crafting.html#item-aliases
local jungle_trunk =  minetest.registered_aliases["mtg_decor_schema:jungle_tree_trunk"] or "mtg_decor_schema:jungle_tree_trunk"
local jungle_leaves = minetest.registered_aliases["mtg_decor_schema:jungle_tree_leaves"] or "mtg_decor_schema:jungle_tree_leaves"

-- tree schematic
local _ = {name = "air", prob = 0}
local L = {name = jungle_leaves, prob = 255}
local N = {name = jungle_leaves, prob = 223}
local M = {name = jungle_leaves, prob = 127}
local B = {name = jungle_trunk, prob = 255, force_place = true}
local U = {name = jungle_trunk, prob = 127, force_place = true}

path.jungle_tree_emergent = {
	size = {x = 7, y = 37, z = 7},
	yslice_prob = {
		{ypos = 13, prob = 127},
		{ypos = 14, prob = 127},
		{ypos = 15, prob = 127},
		{ypos = 16, prob = 127},
		{ypos = 17, prob = 127},
		{ypos = 18, prob = 127},
		{ypos = 19, prob = 127},
		{ypos = 20, prob = 127},
		{ypos = 21, prob = 127},
		{ypos = 22, prob = 127},
		{ypos = 23, prob = 127},
		{ypos = 24, prob = 127},
	},
	data = {
		_, _, _, _, _, _, _,
		_, _, _, _, _, _, _,
		_, _, _, _, _, _, _,
		B, _, _, _, _, _, B,
		B, _, _, _, _, _, B,
		B, _, _, _, _, _, B,
		U, _, _, _, _, _, U,
		_, _, _, _, _, _, _,
		_, _, _, _, _, _, _,
		_, _, _, _, _, _, _,
		_, _, _, _, _, _, _,
		_, _, _, _, _, _, _,
		_, _, _, _, _, _, _,
		_, _, _, _, _, _, _,
		_, _, _, _, _, _, _,
		_, _, _, _, _, _, _,
		_, _, _, _, _, _, _,
		_, _, _, _, _, _, _,
		_, _, _, _, _, _, _,
		N, N, N, _, _, _, _,
		_, _, _, _, _, _, _,
		_, _, _, _, N, N, N,
		_, _, _, _, _, _, _,
		_, _, _, _, _, _, _,
		_, _, N, N, N, _, _,
		_, _, _, _, _, _, _,
		_, _, _, _, _, _, _,
		N, N, N, _, _, _, _,
		_, _, _, _, _, _, _,
		_, _, _, _, N, N, N,
		_, _, _, _, _, _, _,
		_, _, _, _, _, _, _,
		_, M, M, M, M, M, _,
		_, N, N, N, N, N, _,
		_, N, N, N, N, N, _,
		_, N, N, N, N, N, _,
		_, _, _, _, _, _, _,

		_, _, _, _, _, _, _,
		_, _, B, _, B, _, _,
		_, B, B, _, B, B, _,
		_, B, B, _, B, B, _,
		_, B, B, _, B, B, _,
		_, B, B, _, B, B, _,
		_, B, B, _, B, B, _,
		_, U, B, _, B, U, _,
		_, _, U, _, U, _, _,
		_, _, _, _, _, _, _,
		_, _, _, _, _, _, _,
		_, _, _, _, _, _, _,
		_, _, _, _, _, _, _,
		_, _, _, _, _, _, _,
		_, _, _, _, _, _, _,
		_, _, _, _, _, _, _,
		_, _, _, _, _, _, _,
		_, _, _, _, _, _, _,
		_, _, _, _, _, _, _,
		N, B, N, _, _, _, _,
		_, _, _, _, _, _, _,
		_, _, _, _, N, B, N,
		_, _, _, _, _, _, _,
		_, _, _, _, _, _, _,
		_, _, N, B, N, _, _,
		_, _, _, _, _, _, _,
		_, _, _, _, _, _, _,
		N, B, N, _, _, _, _,
		_, _, _, _, _, _, _,
		_, _, _, _, N, B, N,
		_, _, _, _, _, _, _,
		_, _, _, _, _, _, _,
		M, _, _, _, _, _, M,
		N, L, _, _, _, L, N,
		N, B, L, L, L, B, N,
		N, L, L, L, L, L, N,
		_, N, N, N, N, N, _,

		_, _, B, _, B, _, _,
		_, B, B, _, B, B, _,
		_, B, B, _, B, B, _,
		_, B, B, _, B, B, _,
		_, B, B, B, B, B, _,
		_, B, B, B, B, B, _,
		_, B, B, B, B, B, _,
		_, B, B, B, B, B, _,
		_, U, B, B, B, U, _,
		_, _, B, B, B, _, _,
		_, _, B, B, B, _, _,
		_, _, B, B, B, _, _,
		_, _, B, B, B, _, _,
		_, _, B, B, B, _, _,
		_, _, B, B, B, _, _,
		_, _, B, B, B, _, _,
		_, _, B, B, B, _, _,
		_, _, B, B, B, _, _,
		_, _, B, B, B, _, _,
		N, N, B, B, B, _, _,
		_, _, B, B, B, _, _,
		_, _, _, B, B, N, N,
		N, N, N, B, _, _, _,
		_, _, _, B, _, _, _,
		_, _, N, B, N, _, _,
		_, _, _, B, _, _, _,
		_, _, _, B, N, N, N,
		N, N, B, B, _, _, _,
		_, _, _, B, _, _, _,
		_, _, _, B, B, N, N,
		N, N, N, B, _, _, _,
		_, _, _, B, _, _, _,
		M, _, B, B, B, _, M,
		N, _, B, _, B, _, N,
		N, L, L, _, L, L, N,
		N, L, L, L, L, L, N,
		_, N, L, L, L, N, _,

		_, _, _, _, _, _, _,
		_, _, _, _, _, _, _,
		_, _, _, _, _, _, _,
		_, _, _, _, _, _, _,
		_, _, B, B, B, _, _,
		_, _, B, B, B, _, _,
		_, _, B, B, B, _, _,
		_, _, B, B, B, _, _,
		_, _, B, B, B, _, _,
		_, _, B, B, B, _, _,
		_, _, B, B, B, _, _,
		_, _, B, B, B, _, _,
		_, _, B, B, B, _, _,
		_, _, B, B, B, _, _,
		_, _, B, B, B, _, _,
		_, _, B, B, B, _, _,
		_, _, B, B, B, _, _,
		_, _, B, B, B, _, _,
		_, _, B, B, B, _, _,
		_, _, B, B, B, _, _,
		_, _, B, B, B, _, _,
		_, _, B, B, B, _, _,
		N, B, B, B, B, _, _,
		_, _, B, B, B, _, _,
		_, _, B, B, B, _, _,
		_, _, B, B, B, _, _,
		_, _, B, B, B, B, N,
		_, _, B, B, B, _, _,
		_, _, B, B, B, _, _,
		_, _, B, B, B, _, _,
		N, B, B, B, B, _, _,
		_, _, B, B, B, _, _,
		M, _, B, _, B, _, M,
		N, _, _, _, _, _, N,
		N, L, _, _, _, L, N,
		N, L, L, L, L, L, N,
		_, N, L, L, L, N, _,

		_, _, B, _, B, _, _,
		_, B, B, _, B, B, _,
		_, B, B, _, B, B, _,
		_, B, B, _, B, B, _,
		_, B, B, B, B, B, _,
		_, B, B, B, B, B, _,
		_, B, B, B, B, B, _,
		_, B, B, B, B, B, _,
		_, U, B, B, B, U, _,
		_, _, B, B, B, _, _,
		_, _, B, B, B, _, _,
		_, _, B, B, B, _, _,
		_, _, B, B, B, _, _,
		_, _, B, B, B, _, _,
		_, _, B, B, B, _, _,
		_, _, B, B, B, _, _,
		_, _, B, B, B, _, _,
		_, _, B, B, B, _, _,
		_, _, B, B, B, _, _,
		_, _, B, B, B, _, _,
		_, _, B, B, B, _, _,
		_, _, _, B, _, _, _,
		N, N, N, B, _, _, _,
		_, _, _, B, B, N, N,
		_, _, _, B, _, _, _,
		N, N, B, B, _, _, _,
		_, _, _, B, N, N, N,
		_, _, _, B, _, _, _,
		_, _, N, B, N, _, _,
		_, _, _, B, _, _, _,
		N, N, N, B, _, _, _,
		_, _, _, B, _, _, _,
		M, _, B, B, B, _, M,
		N, _, B, _, B, _, N,
		N, L, L, _, L, L, N,
		N, L, L, L, L, L, N,
		_, N, L, L, L, N, _,

		_, _, _, _, _, _, _,
		_, _, B, _, B, _, _,
		_, B, B, _, B, B, _,
		_, B, B, _, B, B, _,
		_, B, B, _, B, B, _,
		_, B, B, _, B, B, _,
		_, B, B, _, B, B, _,
		_, U, B, _, B, U, _,
		_, _, U, _, U, _, _,
		_, _, _, _, _, _, _,
		_, _, _, _, _, _, _,
		_, _, _, _, _, _, _,
		_, _, _, _, _, _, _,
		_, _, _, _, _, _, _,
		_, _, _, _, _, _, _,
		_, _, _, _, _, _, _,
		_, _, _, _, _, _, _,
		_, _, _, _, _, _, _,
		_, _, _, _, _, _, _,
		_, _, _, _, _, _, _,
		_, _, N, B, N, _, _,
		_, _, _, _, _, _, _,
		_, _, _, _, _, _, _,
		_, _, _, _, N, B, N,
		_, _, _, _, _, _, _,
		N, B, N, _, _, _, _,
		_, _, _, _, _, _, _,
		_, _, _, _, _, _, _,
		_, _, N, B, N, _, _,
		_, _, _, _, _, _, _,
		_, _, _, _, _, _, _,
		_, _, _, _, _, _, _,
		M, _, _, _, _, _, M,
		N, L, _, _, _, L, N,
		N, B, L, L, L, B, N,
		N, L, L, L, L, L, N,
		_, N, N, N, N, N, _,

		_, _, _, _, _, _, _,
		_, _, _, _, _, _, _,
		_, _, _, _, _, _, _,
		B, _, _, _, _, _, B,
		B, _, _, _, _, _, B,
		B, _, _, _, _, _, B,
		U, _, _, _, _, _, U,
		_, _, _, _, _, _, _,
		_, _, _, _, _, _, _,
		_, _, _, _, _, _, _,
		_, _, _, _, _, _, _,
		_, _, _, _, _, _, _,
		_, _, _, _, _, _, _,
		_, _, _, _, _, _, _,
		_, _, _, _, _, _, _,
		_, _, _, _, _, _, _,
		_, _, _, _, _, _, _,
		_, _, _, _, _, _, _,
		_, _, _, _, _, _, _,
		_, _, _, _, _, _, _,
		_, _, N, N, N, _, _,
		_, _, _, _, _, _, _,
		_, _, _, _, _, _, _,
		_, _, _, _, N, N, N,
		_, _, _, _, _, _, _,
		N, N, N, _, _, _, _,
		_, _, _, _, _, _, _,
		_, _, _, _, _, _, _,
		_, _, N, N, N, _, _,
		_, _, _, _, _, _, _,
		_, _, _, _, _, _, _,
		_, _, _, _, _, _, _,
		_, M, M, M, M, M, _,
		_, N, N, N, N, N, _,
		_, N, N, N, N, N, _,
		_, N, N, N, N, N, _,
		_, _, _, _, _, _, _,
	},
}